Randome genes :[True, 32, 3, False, 'relu', True, 4, False, 0.3, False, 16, 7, False, 'relu', True, 4, True, 0.4, False, 32, 7, True, 'relu', False, 2, False, 0.3, True, 16, 7, False, 'relu', True, 4, True, 0.5, True, 32, 5, True, 'tanh', True, 2, False, 0.4, False, 32, True, 'relu', False, 0.4, True, 64, False, 'relu', True, 0.5, False, 32, True, 'tanh', True, 0.5]
Traceback (most recent call last):
  File "/home/domenico/anaconda3/envs/gpu/lib/python3.6/site-packages/tensorflow/python/framework/ops.py", line 1576, in _create_c_op
    c_op = c_api.TF_FinishOperation(op_desc)
tensorflow.python.framework.errors_impl.InvalidArgumentError: Negative dimension size caused by subtracting 4 from 2 for 'max_pooling2d_11/MaxPool' (op: 'MaxPool') with input shapes: [?,2,2,16].

During handling of the above exception, another exception occurred:

Traceback (most recent call last):
  File "ai.py", line 251, in <module>
    main()
  File "ai.py", line 233, in main
    accuracy = createAndEvaluate(genoma, x_train,x_test,y_train,y_test)
  File "ai.py", line 188, in createAndEvaluate
    model = createModelFromGenotype (genome,x_train)
  File "ai.py", line 145, in createModelFromGenotype
    model.add( MaxPooling2D ( pool_size = (row[6], row[6]) ) )
  File "/home/domenico/anaconda3/envs/gpu/lib/python3.6/site-packages/keras/engine/sequential.py", line 181, in add
    output_tensor = layer(self.outputs[0])
  File "/home/domenico/anaconda3/envs/gpu/lib/python3.6/site-packages/keras/engine/base_layer.py", line 457, in __call__
    output = self.call(inputs, **kwargs)
  File "/home/domenico/anaconda3/envs/gpu/lib/python3.6/site-packages/keras/layers/pooling.py", line 205, in call
    data_format=self.data_format)
  File "/home/domenico/anaconda3/envs/gpu/lib/python3.6/site-packages/keras/layers/pooling.py", line 268, in _pooling_function
    pool_mode='max')
  File "/home/domenico/anaconda3/envs/gpu/lib/python3.6/site-packages/keras/backend/tensorflow_backend.py", line 3978, in pool2d
    data_format=tf_data_format)
  File "/home/domenico/anaconda3/envs/gpu/lib/python3.6/site-packages/tensorflow/python/ops/nn_ops.py", line 2154, in max_pool
    name=name)
  File "/home/domenico/anaconda3/envs/gpu/lib/python3.6/site-packages/tensorflow/python/ops/gen_nn_ops.py", line 4640, in max_pool
    data_format=data_format, name=name)
  File "/home/domenico/anaconda3/envs/gpu/lib/python3.6/site-packages/tensorflow/python/framework/op_def_library.py", line 787, in _apply_op_helper
    op_def=op_def)
  File "/home/domenico/anaconda3/envs/gpu/lib/python3.6/site-packages/tensorflow/python/util/deprecation.py", line 454, in new_func
    return func(*args, **kwargs)
  File "/home/domenico/anaconda3/envs/gpu/lib/python3.6/site-packages/tensorflow/python/framework/ops.py", line 3155, in create_op
    op_def=op_def)
  File "/home/domenico/anaconda3/envs/gpu/lib/python3.6/site-packages/tensorflow/python/framework/ops.py", line 1731, in __init__
    control_input_ops)
  File "/home/domenico/anaconda3/envs/gpu/lib/python3.6/site-packages/tensorflow/python/framework/ops.py", line 1579, in _create_c_op
    raise ValueError(str(e))
ValueError: Negative dimension size caused by subtracting 4 from 2 for 'max_pooling2d_11/MaxPool' (op: 'MaxPool') with input shapes: [?,2,2,16].
